import { Request, Response } from "express";
import {
  register,
  login,
  deleteUser,
  getAllUsers,
  getUserById,
} from "../services/userService";

export const registerUser = async (req: Request, res: Response) => {
  try {
    const { username, email, password } = req.body;
    const user = await register(username, email, password);
    res.status(201).json(user);
  } catch (error) {
    res.status(500).json({
      error: error instanceof Error ? error.message : "Unknown error",
    });
  }
};

export const loginUser = async (req: Request, res: Response) => {
  try {
    const { username, password } = req.body;
    const result = await login(username, password);
    res.status(200).json(result);
  } catch (error) {
    res.status(500).json({
      error: error instanceof Error ? error.message : "Unknown error",
    });
  }
};

export const getAllUsersController = async (
  req: Request,
  res: Response
): Promise<void> => {
  try {
    const users = await getAllUsers();
    res.status(200).json(users);
  } catch (error) {
    if (error instanceof Error) {
      res.status(500).json({ message: error.message });
    } else {
      res.status(500).json({ message: "An unexpected error occurred." });
    }
  }
};

export const getUserByIdController = async (
  req: Request,
  res: Response
): Promise<void> => {
  try {
    const { id } = req.params;
    const user = await getUserById(id);
    res.status(200).json(user);
  } catch (error) {
    if (error instanceof Error) {
      res.status(500).json({ message: error.message });
    } else {
      res.status(500).json({ message: "An unexpected error occurred." });
    }
  }
};

export const deleteUserController = async (
  req: Request,
  res: Response
): Promise<void> => {
  const { id } = req.params;

  try {
    const result = await deleteUser(id);
    res.status(200).json({ message: result.message });
  } catch (error) {
    if (error instanceof Error) {
      res.status(500).json({ message: error.message });
    } else {
      res.status(500).json({ message: "An unexpected error occurred." });
    }
  }
};
